[2019-04-29 04:17:45 +0530] [53334] [INFO] Starting gunicorn 19.9.0
[2019-04-29 04:17:45 +0530] [53334] [INFO] Listening at: unix:/home/devanks/AttendanceMgmtAI/Backend/gunicorn.sock (53334)
[2019-04-29 04:17:45 +0530] [53334] [INFO] Using worker: sync
[2019-04-29 04:17:45 +0530] [53337] [INFO] Booting worker with pid: 53337
[2019-04-29 04:17:45 +0530] [53338] [INFO] Booting worker with pid: 53338
[2019-04-29 04:17:45 +0530] [53341] [INFO] Booting worker with pid: 53341
[2019-04-29 04:18:17 +0530] [53334] [INFO] Handling signal: term
[2019-04-28 22:48:17 +0000] [53338] [INFO] Worker exiting (pid: 53338)
[2019-04-28 22:48:17 +0000] [53341] [INFO] Worker exiting (pid: 53341)
[2019-04-28 22:48:17 +0000] [53337] [INFO] Worker exiting (pid: 53337)
[2019-04-29 04:18:17 +0530] [53334] [INFO] Shutting down: Master
usage: gunicorn [OPTIONS] [APP_MODULE]
gunicorn: error: No application module specified.
usage: gunicorn [OPTIONS] [APP_MODULE]
gunicorn: error: No application module specified.
usage: gunicorn [OPTIONS] [APP_MODULE]
gunicorn: error: No application module specified.
usage: gunicorn [OPTIONS] [APP_MODULE]
gunicorn: error: No application module specified.
usage: gunicorn [OPTIONS] [APP_MODULE]
gunicorn: error: No application module specified.
usage: gunicorn [OPTIONS] [APP_MODULE]
gunicorn: error: No application module specified.
usage: gunicorn [OPTIONS] [APP_MODULE]
gunicorn: error: No application module specified.
usage: gunicorn [OPTIONS] [APP_MODULE]
gunicorn: error: No application module specified.
[2019-04-29 04:20:17 +0530] [53788] [INFO] Starting gunicorn 19.9.0
[2019-04-29 04:20:17 +0530] [53788] [INFO] Listening at: http://0.0.0.0:8001 (53788)
[2019-04-29 04:20:17 +0530] [53788] [INFO] Using worker: sync
[2019-04-29 04:20:17 +0530] [53795] [INFO] Booting worker with pid: 53795
[2019-04-29 04:20:17 +0530] [53796] [INFO] Booting worker with pid: 53796
[2019-04-29 04:20:17 +0530] [53799] [INFO] Booting worker with pid: 53799
Not Found: /static/notifications/notify.js
Not Found: /favicon.ico
Not Found: /static/notifications/notify.js
Not Found: /static/notifications/notify.js
Not Found: /static/notifications/notify.js
Forbidden (CSRF token missing or incorrect.): /accounts/login/
Forbidden (CSRF token missing or incorrect.): /accounts/login/
Forbidden (CSRF token missing or incorrect.): /accounts/login/
Not Found: /static/notifications/notify.js
Not Found: /static/notifications/notify.js
Not Found: /static/notifications/notify.js
Not Found: /static/notifications/notify.js
Not Found: /static/notifications/notify.js
Not Found: /static/notifications/notify.js
Not Found: /static/notifications/notify.js
/home/devanks/pythonMainProject/lib/python3.6/site-packages/django/db/models/fields/__init__.py:1421: RuntimeWarning: DateTimeField SessionRecord.DateOfClass received a naive datetime (2019-04-28 22:55:35.179956) while time zone support is active.
  RuntimeWarning)
Not Found: /static/notifications/notify.js
Not Found: /static/notifications/notify.js
Not Found: /static/notifications/notify.js
Not Found: /static/notifications/notify.js
Not Found: /favicon.ico
Not Found: /favicon.ico
Not Found: /static/notifications/notify.js
Not Found: /static/notifications/notify.js
Not Found: /static/notifications/notify.js
Not Found: /static/notifications/notify.js
Not Found: /static/notifications/notify.js
Not Found: /favicon.ico
Not Found: /static/notifications/notify.js
Not Found: /static/notifications/notify.js
Not Found: /favicon.ico
Not Found: /static/notifications/notify.js
Not Found: /static/notifications/notify.js
Not Found: /static/notifications/notify.js
Not Found: /static/notifications/notify.js
Not Found: /static/notifications/notify.js
Not Found: /static/notifications/notify.js
Not Found: /static/notifications/notify.js
Not Found: /.git/index
Not Found: /.git/config
Not Found: /static/notifications/notify.js
Not Found: /static/notifications/notify.js
Not Found: /static/notifications/notify.js
Not Found: /favicon.ico
Not Found: /favicon.ico
Not Found: /static/notifications/notify.js
Not Found: /static/notifications/notify.js
Not Found: /static/notifications/notify.js
Not Found: /static/notifications/notify.js
Not Found: /static/notifications/notify.js
Not Found: /static/notifications/notify.js
Not Found: /static/notifications/notify.js
Not Found: /favicon.ico
Not Found: /static/notifications/notify.js
Not Found: /static/notifications/notify.js
Not Found: /static/notifications/notify.js
Not Found: /static/notifications/notify.js
Not Found: /favicon.ico
Not Found: /static/notifications/notify.js
Not Found: /favicon.ico
Not Found: /static/notifications/notify.js
Not Found: /static/notifications/notify.js
[2019-04-29 05:34:38 +0530] [53788] [INFO] Handling signal: term
[2019-04-29 00:04:38 +0000] [53795] [INFO] Worker exiting (pid: 53795)
[2019-04-29 00:04:38 +0000] [53796] [INFO] Worker exiting (pid: 53796)
[2019-04-29 00:04:38 +0000] [53799] [INFO] Worker exiting (pid: 53799)
[2019-04-29 05:34:39 +0530] [53788] [INFO] Shutting down: Master
[2019-04-29 05:34:42 +0530] [4634] [INFO] Starting gunicorn 19.9.0
[2019-04-29 05:34:42 +0530] [4634] [INFO] Listening at: http://0.0.0.0:8001 (4634)
[2019-04-29 05:34:42 +0530] [4634] [INFO] Using worker: sync
[2019-04-29 05:34:42 +0530] [4637] [INFO] Booting worker with pid: 4637
[2019-04-29 05:34:42 +0530] [4638] [INFO] Booting worker with pid: 4638
[2019-04-29 05:34:42 +0530] [4639] [INFO] Booting worker with pid: 4639
[2019-04-29 05:34:47 +0530] [4634] [INFO] Handling signal: term
[2019-04-29 00:04:47 +0000] [4638] [INFO] Worker exiting (pid: 4638)
[2019-04-29 00:04:47 +0000] [4637] [INFO] Worker exiting (pid: 4637)
[2019-04-29 00:04:47 +0000] [4639] [INFO] Worker exiting (pid: 4639)
[2019-04-29 05:34:48 +0530] [4634] [INFO] Shutting down: Master
[2019-04-29 05:34:48 +0530] [4648] [INFO] Starting gunicorn 19.9.0
[2019-04-29 05:34:48 +0530] [4648] [INFO] Listening at: http://0.0.0.0:8001 (4648)
[2019-04-29 05:34:48 +0530] [4648] [INFO] Using worker: sync
[2019-04-29 05:34:48 +0530] [4651] [INFO] Booting worker with pid: 4651
[2019-04-29 05:34:48 +0530] [4652] [INFO] Booting worker with pid: 4652
[2019-04-29 05:34:48 +0530] [4655] [INFO] Booting worker with pid: 4655
[2019-04-29 05:35:15 +0530] [4648] [INFO] Handling signal: term
[2019-04-29 00:05:15 +0000] [4655] [INFO] Worker exiting (pid: 4655)
[2019-04-29 00:05:15 +0000] [4652] [INFO] Worker exiting (pid: 4652)
[2019-04-29 00:05:15 +0000] [4651] [INFO] Worker exiting (pid: 4651)
[2019-04-29 05:35:15 +0530] [4648] [INFO] Shutting down: Master
[2019-04-29 06:06:04 +0530] [10731] [INFO] Starting gunicorn 19.9.0
[2019-04-29 06:06:04 +0530] [10731] [INFO] Listening at: http://0.0.0.0:8001 (10731)
[2019-04-29 06:06:04 +0530] [10731] [INFO] Using worker: sync
[2019-04-29 06:06:04 +0530] [10734] [INFO] Booting worker with pid: 10734
[2019-04-29 06:06:04 +0530] [10736] [INFO] Booting worker with pid: 10736
[2019-04-29 06:06:04 +0530] [10738] [INFO] Booting worker with pid: 10738
[2019-04-29 00:36:04 +0000] [10734] [ERROR] Exception in worker process
Traceback (most recent call last):
  File "/home/devanks/pythonMainProject/lib/python3.6/site-packages/gunicorn/arbiter.py", line 583, in spawn_worker
    worker.init_process()
  File "/home/devanks/pythonMainProject/lib/python3.6/site-packages/gunicorn/workers/base.py", line 129, in init_process
    self.load_wsgi()
  File "/home/devanks/pythonMainProject/lib/python3.6/site-packages/gunicorn/workers/base.py", line 138, in load_wsgi
    self.wsgi = self.app.wsgi()
  File "/home/devanks/pythonMainProject/lib/python3.6/site-packages/gunicorn/app/base.py", line 67, in wsgi
    self.callable = self.load()
  File "/home/devanks/pythonMainProject/lib/python3.6/site-packages/gunicorn/app/wsgiapp.py", line 52, in load
    return self.load_wsgiapp()
  File "/home/devanks/pythonMainProject/lib/python3.6/site-packages/gunicorn/app/wsgiapp.py", line 41, in load_wsgiapp
    return util.import_app(self.app_uri)
  File "/home/devanks/pythonMainProject/lib/python3.6/site-packages/gunicorn/util.py", line 350, in import_app
    __import__(module)
  File "/home/devanks/AttendanceMgmtAI/Backend/AttendanceMgmtAI/wsgi.py", line 16, in <module>
    application = get_wsgi_application()
  File "/home/devanks/pythonMainProject/lib/python3.6/site-packages/django/core/wsgi.py", line 12, in get_wsgi_application
    django.setup(set_prefix=False)
  File "/home/devanks/pythonMainProject/lib/python3.6/site-packages/django/__init__.py", line 24, in setup
    apps.populate(settings.INSTALLED_APPS)
  File "/home/devanks/pythonMainProject/lib/python3.6/site-packages/django/apps/registry.py", line 91, in populate
    app_config = AppConfig.create(entry)
  File "/home/devanks/pythonMainProject/lib/python3.6/site-packages/django/apps/config.py", line 90, in create
    module = import_module(entry)
  File "/home/devanks/pythonMainProject/lib/python3.6/importlib/__init__.py", line 126, in import_module
    return _bootstrap._gcd_import(name[level:], package, level)
ModuleNotFoundError: No module named 'pwa'
[2019-04-29 00:36:04 +0000] [10734] [INFO] Worker exiting (pid: 10734)
[2019-04-29 00:36:04 +0000] [10736] [ERROR] Exception in worker process
Traceback (most recent call last):
  File "/home/devanks/pythonMainProject/lib/python3.6/site-packages/gunicorn/arbiter.py", line 583, in spawn_worker
    worker.init_process()
  File "/home/devanks/pythonMainProject/lib/python3.6/site-packages/gunicorn/workers/base.py", line 129, in init_process
    self.load_wsgi()
  File "/home/devanks/pythonMainProject/lib/python3.6/site-packages/gunicorn/workers/base.py", line 138, in load_wsgi
    self.wsgi = self.app.wsgi()
  File "/home/devanks/pythonMainProject/lib/python3.6/site-packages/gunicorn/app/base.py", line 67, in wsgi
    self.callable = self.load()
  File "/home/devanks/pythonMainProject/lib/python3.6/site-packages/gunicorn/app/wsgiapp.py", line 52, in load
    return self.load_wsgiapp()
  File "/home/devanks/pythonMainProject/lib/python3.6/site-packages/gunicorn/app/wsgiapp.py", line 41, in load_wsgiapp
    return util.import_app(self.app_uri)
  File "/home/devanks/pythonMainProject/lib/python3.6/site-packages/gunicorn/util.py", line 350, in import_app
    __import__(module)
  File "/home/devanks/AttendanceMgmtAI/Backend/AttendanceMgmtAI/wsgi.py", line 16, in <module>
    application = get_wsgi_application()
  File "/home/devanks/pythonMainProject/lib/python3.6/site-packages/django/core/wsgi.py", line 12, in get_wsgi_application
    django.setup(set_prefix=False)
  File "/home/devanks/pythonMainProject/lib/python3.6/site-packages/django/__init__.py", line 24, in setup
    apps.populate(settings.INSTALLED_APPS)
  File "/home/devanks/pythonMainProject/lib/python3.6/site-packages/django/apps/registry.py", line 91, in populate
    app_config = AppConfig.create(entry)
  File "/home/devanks/pythonMainProject/lib/python3.6/site-packages/django/apps/config.py", line 90, in create
    module = import_module(entry)
  File "/home/devanks/pythonMainProject/lib/python3.6/importlib/__init__.py", line 126, in import_module
    return _bootstrap._gcd_import(name[level:], package, level)
ModuleNotFoundError: No module named 'pwa'
[2019-04-29 00:36:04 +0000] [10736] [INFO] Worker exiting (pid: 10736)
Traceback (most recent call last):
  File "/home/devanks/pythonMainProject/lib/python3.6/site-packages/gunicorn/arbiter.py", line 203, in run
    self.manage_workers()
  File "/home/devanks/pythonMainProject/lib/python3.6/site-packages/gunicorn/arbiter.py", line 545, in manage_workers
    self.spawn_workers()
  File "/home/devanks/pythonMainProject/lib/python3.6/site-packages/gunicorn/arbiter.py", line 617, in spawn_workers
    time.sleep(0.1 * random.random())
  File "/home/devanks/pythonMainProject/lib/python3.6/site-packages/gunicorn/arbiter.py", line 245, in handle_chld
    self.reap_workers()
  File "/home/devanks/pythonMainProject/lib/python3.6/site-packages/gunicorn/arbiter.py", line 525, in reap_workers
    raise HaltServer(reason, self.WORKER_BOOT_ERROR)
gunicorn.errors.HaltServer: <HaltServer 'Worker failed to boot.' 3>

During handling of the above exception, another exception occurred:

Traceback (most recent call last):
  File "/home/devanks/pythonMainProject/bin/gunicorn", line 10, in <module>
    sys.exit(run())
  File "/home/devanks/pythonMainProject/lib/python3.6/site-packages/gunicorn/app/wsgiapp.py", line 61, in run
    WSGIApplication("%(prog)s [OPTIONS] [APP_MODULE]").run()
  File "/home/devanks/pythonMainProject/lib/python3.6/site-packages/gunicorn/app/base.py", line 223, in run
    super(Application, self).run()
  File "/home/devanks/pythonMainProject/lib/python3.6/site-packages/gunicorn/app/base.py", line 72, in run
    Arbiter(self).run()
  File "/home/devanks/pythonMainProject/lib/python3.6/site-packages/gunicorn/arbiter.py", line 232, in run
    self.halt(reason=inst.reason, exit_status=inst.exit_status)
  File "/home/devanks/pythonMainProject/lib/python3.6/site-packages/gunicorn/arbiter.py", line 345, in halt
    self.stop()
  File "/home/devanks/pythonMainProject/lib/python3.6/site-packages/gunicorn/arbiter.py", line 393, in stop
    time.sleep(0.1)
  File "/home/devanks/pythonMainProject/lib/python3.6/site-packages/gunicorn/arbiter.py", line 245, in handle_chld
    self.reap_workers()
  File "/home/devanks/pythonMainProject/lib/python3.6/site-packages/gunicorn/arbiter.py", line 525, in reap_workers
    raise HaltServer(reason, self.WORKER_BOOT_ERROR)
gunicorn.errors.HaltServer: <HaltServer 'Worker failed to boot.' 3>
[2019-04-29 00:36:04 +0000] [10738] [ERROR] Exception in worker process
Traceback (most recent call last):
  File "/home/devanks/pythonMainProject/lib/python3.6/site-packages/gunicorn/arbiter.py", line 583, in spawn_worker
    worker.init_process()
  File "/home/devanks/pythonMainProject/lib/python3.6/site-packages/gunicorn/workers/base.py", line 129, in init_process
    self.load_wsgi()
  File "/home/devanks/pythonMainProject/lib/python3.6/site-packages/gunicorn/workers/base.py", line 138, in load_wsgi
    self.wsgi = self.app.wsgi()
  File "/home/devanks/pythonMainProject/lib/python3.6/site-packages/gunicorn/app/base.py", line 67, in wsgi
    self.callable = self.load()
  File "/home/devanks/pythonMainProject/lib/python3.6/site-packages/gunicorn/app/wsgiapp.py", line 52, in load
    return self.load_wsgiapp()
  File "/home/devanks/pythonMainProject/lib/python3.6/site-packages/gunicorn/app/wsgiapp.py", line 41, in load_wsgiapp
    return util.import_app(self.app_uri)
  File "/home/devanks/pythonMainProject/lib/python3.6/site-packages/gunicorn/util.py", line 350, in import_app
    __import__(module)
  File "/home/devanks/AttendanceMgmtAI/Backend/AttendanceMgmtAI/wsgi.py", line 16, in <module>
    application = get_wsgi_application()
  File "/home/devanks/pythonMainProject/lib/python3.6/site-packages/django/core/wsgi.py", line 12, in get_wsgi_application
    django.setup(set_prefix=False)
  File "/home/devanks/pythonMainProject/lib/python3.6/site-packages/django/__init__.py", line 24, in setup
    apps.populate(settings.INSTALLED_APPS)
  File "/home/devanks/pythonMainProject/lib/python3.6/site-packages/django/apps/registry.py", line 91, in populate
    app_config = AppConfig.create(entry)
  File "/home/devanks/pythonMainProject/lib/python3.6/site-packages/django/apps/config.py", line 90, in create
    module = import_module(entry)
  File "/home/devanks/pythonMainProject/lib/python3.6/importlib/__init__.py", line 126, in import_module
    return _bootstrap._gcd_import(name[level:], package, level)
ModuleNotFoundError: No module named 'pwa'
[2019-04-29 00:36:04 +0000] [10738] [INFO] Worker exiting (pid: 10738)
[2019-04-29 06:06:05 +0530] [10740] [INFO] Starting gunicorn 19.9.0
[2019-04-29 06:06:05 +0530] [10740] [INFO] Listening at: http://0.0.0.0:8001 (10740)
[2019-04-29 06:06:05 +0530] [10740] [INFO] Using worker: sync
[2019-04-29 06:06:05 +0530] [10743] [INFO] Booting worker with pid: 10743
[2019-04-29 06:06:05 +0530] [10744] [INFO] Booting worker with pid: 10744
[2019-04-29 06:06:05 +0530] [10745] [INFO] Booting worker with pid: 10745
[2019-04-29 00:36:05 +0000] [10743] [ERROR] Exception in worker process
Traceback (most recent call last):
  File "/home/devanks/pythonMainProject/lib/python3.6/site-packages/gunicorn/arbiter.py", line 583, in spawn_worker
    worker.init_process()
  File "/home/devanks/pythonMainProject/lib/python3.6/site-packages/gunicorn/workers/base.py", line 129, in init_process
    self.load_wsgi()
  File "/home/devanks/pythonMainProject/lib/python3.6/site-packages/gunicorn/workers/base.py", line 138, in load_wsgi
    self.wsgi = self.app.wsgi()
  File "/home/devanks/pythonMainProject/lib/python3.6/site-packages/gunicorn/app/base.py", line 67, in wsgi
    self.callable = self.load()
  File "/home/devanks/pythonMainProject/lib/python3.6/site-packages/gunicorn/app/wsgiapp.py", line 52, in load
    return self.load_wsgiapp()
  File "/home/devanks/pythonMainProject/lib/python3.6/site-packages/gunicorn/app/wsgiapp.py", line 41, in load_wsgiapp
    return util.import_app(self.app_uri)
  File "/home/devanks/pythonMainProject/lib/python3.6/site-packages/gunicorn/util.py", line 350, in import_app
    __import__(module)
  File "/home/devanks/AttendanceMgmtAI/Backend/AttendanceMgmtAI/wsgi.py", line 16, in <module>
    application = get_wsgi_application()
  File "/home/devanks/pythonMainProject/lib/python3.6/site-packages/django/core/wsgi.py", line 12, in get_wsgi_application
    django.setup(set_prefix=False)
  File "/home/devanks/pythonMainProject/lib/python3.6/site-packages/django/__init__.py", line 24, in setup
    apps.populate(settings.INSTALLED_APPS)
  File "/home/devanks/pythonMainProject/lib/python3.6/site-packages/django/apps/registry.py", line 91, in populate
    app_config = AppConfig.create(entry)
  File "/home/devanks/pythonMainProject/lib/python3.6/site-packages/django/apps/config.py", line 90, in create
    module = import_module(entry)
  File "/home/devanks/pythonMainProject/lib/python3.6/importlib/__init__.py", line 126, in import_module
    return _bootstrap._gcd_import(name[level:], package, level)
ModuleNotFoundError: No module named 'pwa'
[2019-04-29 00:36:05 +0000] [10743] [INFO] Worker exiting (pid: 10743)
[2019-04-29 00:36:05 +0000] [10745] [ERROR] Exception in worker process
Traceback (most recent call last):
  File "/home/devanks/pythonMainProject/lib/python3.6/site-packages/gunicorn/arbiter.py", line 583, in spawn_worker
    worker.init_process()
  File "/home/devanks/pythonMainProject/lib/python3.6/site-packages/gunicorn/workers/base.py", line 129, in init_process
    self.load_wsgi()
  File "/home/devanks/pythonMainProject/lib/python3.6/site-packages/gunicorn/workers/base.py", line 138, in load_wsgi
    self.wsgi = self.app.wsgi()
  File "/home/devanks/pythonMainProject/lib/python3.6/site-packages/gunicorn/app/base.py", line 67, in wsgi
    self.callable = self.load()
  File "/home/devanks/pythonMainProject/lib/python3.6/site-packages/gunicorn/app/wsgiapp.py", line 52, in load
    return self.load_wsgiapp()
  File "/home/devanks/pythonMainProject/lib/python3.6/site-packages/gunicorn/app/wsgiapp.py", line 41, in load_wsgiapp
    return util.import_app(self.app_uri)
  File "/home/devanks/pythonMainProject/lib/python3.6/site-packages/gunicorn/util.py", line 350, in import_app
    __import__(module)
  File "/home/devanks/AttendanceMgmtAI/Backend/AttendanceMgmtAI/wsgi.py", line 16, in <module>
    application = get_wsgi_application()
  File "/home/devanks/pythonMainProject/lib/python3.6/site-packages/django/core/wsgi.py", line 12, in get_wsgi_application
    django.setup(set_prefix=False)
  File "/home/devanks/pythonMainProject/lib/python3.6/site-packages/django/__init__.py", line 24, in setup
    apps.populate(settings.INSTALLED_APPS)
  File "/home/devanks/pythonMainProject/lib/python3.6/site-packages/django/apps/registry.py", line 91, in populate
    app_config = AppConfig.create(entry)
  File "/home/devanks/pythonMainProject/lib/python3.6/site-packages/django/apps/config.py", line 90, in create
    module = import_module(entry)
  File "/home/devanks/pythonMainProject/lib/python3.6/importlib/__init__.py", line 126, in import_module
    return _bootstrap._gcd_import(name[level:], package, level)
ModuleNotFoundError: No module named 'pwa'
[2019-04-29 00:36:05 +0000] [10745] [INFO] Worker exiting (pid: 10745)
[2019-04-29 00:36:05 +0000] [10744] [ERROR] Exception in worker process
Traceback (most recent call last):
  File "/home/devanks/pythonMainProject/lib/python3.6/site-packages/gunicorn/arbiter.py", line 583, in spawn_worker
    worker.init_process()
  File "/home/devanks/pythonMainProject/lib/python3.6/site-packages/gunicorn/workers/base.py", line 129, in init_process
    self.load_wsgi()
  File "/home/devanks/pythonMainProject/lib/python3.6/site-packages/gunicorn/workers/base.py", line 138, in load_wsgi
    self.wsgi = self.app.wsgi()
  File "/home/devanks/pythonMainProject/lib/python3.6/site-packages/gunicorn/app/base.py", line 67, in wsgi
    self.callable = self.load()
  File "/home/devanks/pythonMainProject/lib/python3.6/site-packages/gunicorn/app/wsgiapp.py", line 52, in load
    return self.load_wsgiapp()
  File "/home/devanks/pythonMainProject/lib/python3.6/site-packages/gunicorn/app/wsgiapp.py", line 41, in load_wsgiapp
    return util.import_app(self.app_uri)
  File "/home/devanks/pythonMainProject/lib/python3.6/site-packages/gunicorn/util.py", line 350, in import_app
    __import__(module)
  File "/home/devanks/AttendanceMgmtAI/Backend/AttendanceMgmtAI/wsgi.py", line 16, in <module>
    application = get_wsgi_application()
  File "/home/devanks/pythonMainProject/lib/python3.6/site-packages/django/core/wsgi.py", line 12, in get_wsgi_application
    django.setup(set_prefix=False)
  File "/home/devanks/pythonMainProject/lib/python3.6/site-packages/django/__init__.py", line 24, in setup
    apps.populate(settings.INSTALLED_APPS)
  File "/home/devanks/pythonMainProject/lib/python3.6/site-packages/django/apps/registry.py", line 91, in populate
    app_config = AppConfig.create(entry)
  File "/home/devanks/pythonMainProject/lib/python3.6/site-packages/django/apps/config.py", line 90, in create
    module = import_module(entry)
  File "/home/devanks/pythonMainProject/lib/python3.6/importlib/__init__.py", line 126, in import_module
    return _bootstrap._gcd_import(name[level:], package, level)
ModuleNotFoundError: No module named 'pwa'
[2019-04-29 00:36:05 +0000] [10744] [INFO] Worker exiting (pid: 10744)
[2019-04-29 06:06:05 +0530] [10740] [INFO] Shutting down: Master
[2019-04-29 06:06:05 +0530] [10740] [INFO] Reason: Worker failed to boot.
[2019-04-29 06:06:07 +0530] [10759] [INFO] Starting gunicorn 19.9.0
[2019-04-29 06:06:07 +0530] [10759] [INFO] Listening at: http://0.0.0.0:8001 (10759)
[2019-04-29 06:06:07 +0530] [10759] [INFO] Using worker: sync
[2019-04-29 06:06:07 +0530] [10762] [INFO] Booting worker with pid: 10762
[2019-04-29 06:06:07 +0530] [10763] [INFO] Booting worker with pid: 10763
[2019-04-29 06:06:07 +0530] [10764] [INFO] Booting worker with pid: 10764
[2019-04-29 00:36:08 +0000] [10762] [ERROR] Exception in worker process
Traceback (most recent call last):
  File "/home/devanks/pythonMainProject/lib/python3.6/site-packages/gunicorn/arbiter.py", line 583, in spawn_worker
    worker.init_process()
  File "/home/devanks/pythonMainProject/lib/python3.6/site-packages/gunicorn/workers/base.py", line 129, in init_process
    self.load_wsgi()
  File "/home/devanks/pythonMainProject/lib/python3.6/site-packages/gunicorn/workers/base.py", line 138, in load_wsgi
    self.wsgi = self.app.wsgi()
  File "/home/devanks/pythonMainProject/lib/python3.6/site-packages/gunicorn/app/base.py", line 67, in wsgi
    self.callable = self.load()
  File "/home/devanks/pythonMainProject/lib/python3.6/site-packages/gunicorn/app/wsgiapp.py", line 52, in load
    return self.load_wsgiapp()
  File "/home/devanks/pythonMainProject/lib/python3.6/site-packages/gunicorn/app/wsgiapp.py", line 41, in load_wsgiapp
    return util.import_app(self.app_uri)
  File "/home/devanks/pythonMainProject/lib/python3.6/site-packages/gunicorn/util.py", line 350, in import_app
    __import__(module)
  File "/home/devanks/AttendanceMgmtAI/Backend/AttendanceMgmtAI/wsgi.py", line 16, in <module>
    application = get_wsgi_application()
  File "/home/devanks/pythonMainProject/lib/python3.6/site-packages/django/core/wsgi.py", line 12, in get_wsgi_application
    django.setup(set_prefix=False)
  File "/home/devanks/pythonMainProject/lib/python3.6/site-packages/django/__init__.py", line 24, in setup
    apps.populate(settings.INSTALLED_APPS)
  File "/home/devanks/pythonMainProject/lib/python3.6/site-packages/django/apps/registry.py", line 91, in populate
    app_config = AppConfig.create(entry)
  File "/home/devanks/pythonMainProject/lib/python3.6/site-packages/django/apps/config.py", line 90, in create
    module = import_module(entry)
  File "/home/devanks/pythonMainProject/lib/python3.6/importlib/__init__.py", line 126, in import_module
    return _bootstrap._gcd_import(name[level:], package, level)
ModuleNotFoundError: No module named 'pwa'
[2019-04-29 00:36:08 +0000] [10762] [INFO] Worker exiting (pid: 10762)
[2019-04-29 00:36:08 +0000] [10763] [ERROR] Exception in worker process
Traceback (most recent call last):
  File "/home/devanks/pythonMainProject/lib/python3.6/site-packages/gunicorn/arbiter.py", line 583, in spawn_worker
    worker.init_process()
  File "/home/devanks/pythonMainProject/lib/python3.6/site-packages/gunicorn/workers/base.py", line 129, in init_process
    self.load_wsgi()
  File "/home/devanks/pythonMainProject/lib/python3.6/site-packages/gunicorn/workers/base.py", line 138, in load_wsgi
    self.wsgi = self.app.wsgi()
  File "/home/devanks/pythonMainProject/lib/python3.6/site-packages/gunicorn/app/base.py", line 67, in wsgi
    self.callable = self.load()
  File "/home/devanks/pythonMainProject/lib/python3.6/site-packages/gunicorn/app/wsgiapp.py", line 52, in load
    return self.load_wsgiapp()
  File "/home/devanks/pythonMainProject/lib/python3.6/site-packages/gunicorn/app/wsgiapp.py", line 41, in load_wsgiapp
    return util.import_app(self.app_uri)
  File "/home/devanks/pythonMainProject/lib/python3.6/site-packages/gunicorn/util.py", line 350, in import_app
    __import__(module)
  File "/home/devanks/AttendanceMgmtAI/Backend/AttendanceMgmtAI/wsgi.py", line 16, in <module>
    application = get_wsgi_application()
  File "/home/devanks/pythonMainProject/lib/python3.6/site-packages/django/core/wsgi.py", line 12, in get_wsgi_application
    django.setup(set_prefix=False)
  File "/home/devanks/pythonMainProject/lib/python3.6/site-packages/django/__init__.py", line 24, in setup
    apps.populate(settings.INSTALLED_APPS)
  File "/home/devanks/pythonMainProject/lib/python3.6/site-packages/django/apps/registry.py", line 91, in populate
    app_config = AppConfig.create(entry)
  File "/home/devanks/pythonMainProject/lib/python3.6/site-packages/django/apps/config.py", line 90, in create
    module = import_module(entry)
  File "/home/devanks/pythonMainProject/lib/python3.6/importlib/__init__.py", line 126, in import_module
    return _bootstrap._gcd_import(name[level:], package, level)
ModuleNotFoundError: No module named 'pwa'
[2019-04-29 00:36:08 +0000] [10763] [INFO] Worker exiting (pid: 10763)
[2019-04-29 00:36:08 +0000] [10764] [ERROR] Exception in worker process
Traceback (most recent call last):
  File "/home/devanks/pythonMainProject/lib/python3.6/site-packages/gunicorn/arbiter.py", line 583, in spawn_worker
    worker.init_process()
  File "/home/devanks/pythonMainProject/lib/python3.6/site-packages/gunicorn/workers/base.py", line 129, in init_process
    self.load_wsgi()
  File "/home/devanks/pythonMainProject/lib/python3.6/site-packages/gunicorn/workers/base.py", line 138, in load_wsgi
    self.wsgi = self.app.wsgi()
  File "/home/devanks/pythonMainProject/lib/python3.6/site-packages/gunicorn/app/base.py", line 67, in wsgi
    self.callable = self.load()
  File "/home/devanks/pythonMainProject/lib/python3.6/site-packages/gunicorn/app/wsgiapp.py", line 52, in load
    return self.load_wsgiapp()
  File "/home/devanks/pythonMainProject/lib/python3.6/site-packages/gunicorn/app/wsgiapp.py", line 41, in load_wsgiapp
    return util.import_app(self.app_uri)
  File "/home/devanks/pythonMainProject/lib/python3.6/site-packages/gunicorn/util.py", line 350, in import_app
    __import__(module)
  File "/home/devanks/AttendanceMgmtAI/Backend/AttendanceMgmtAI/wsgi.py", line 16, in <module>
    application = get_wsgi_application()
  File "/home/devanks/pythonMainProject/lib/python3.6/site-packages/django/core/wsgi.py", line 12, in get_wsgi_application
    django.setup(set_prefix=False)
  File "/home/devanks/pythonMainProject/lib/python3.6/site-packages/django/__init__.py", line 24, in setup
    apps.populate(settings.INSTALLED_APPS)
  File "/home/devanks/pythonMainProject/lib/python3.6/site-packages/django/apps/registry.py", line 91, in populate
    app_config = AppConfig.create(entry)
  File "/home/devanks/pythonMainProject/lib/python3.6/site-packages/django/apps/config.py", line 90, in create
    module = import_module(entry)
  File "/home/devanks/pythonMainProject/lib/python3.6/importlib/__init__.py", line 126, in import_module
    return _bootstrap._gcd_import(name[level:], package, level)
ModuleNotFoundError: No module named 'pwa'
[2019-04-29 00:36:08 +0000] [10764] [INFO] Worker exiting (pid: 10764)
Traceback (most recent call last):
  File "/home/devanks/pythonMainProject/lib/python3.6/site-packages/gunicorn/arbiter.py", line 210, in run
    self.sleep()
  File "/home/devanks/pythonMainProject/lib/python3.6/site-packages/gunicorn/arbiter.py", line 360, in sleep
    ready = select.select([self.PIPE[0]], [], [], 1.0)
  File "/home/devanks/pythonMainProject/lib/python3.6/site-packages/gunicorn/arbiter.py", line 245, in handle_chld
    self.reap_workers()
  File "/home/devanks/pythonMainProject/lib/python3.6/site-packages/gunicorn/arbiter.py", line 525, in reap_workers
    raise HaltServer(reason, self.WORKER_BOOT_ERROR)
gunicorn.errors.HaltServer: <HaltServer 'Worker failed to boot.' 3>

During handling of the above exception, another exception occurred:

Traceback (most recent call last):
  File "/home/devanks/pythonMainProject/bin/gunicorn", line 10, in <module>
    sys.exit(run())
  File "/home/devanks/pythonMainProject/lib/python3.6/site-packages/gunicorn/app/wsgiapp.py", line 61, in run
    WSGIApplication("%(prog)s [OPTIONS] [APP_MODULE]").run()
  File "/home/devanks/pythonMainProject/lib/python3.6/site-packages/gunicorn/app/base.py", line 223, in run
    super(Application, self).run()
  File "/home/devanks/pythonMainProject/lib/python3.6/site-packages/gunicorn/app/base.py", line 72, in run
    Arbiter(self).run()
  File "/home/devanks/pythonMainProject/lib/python3.6/site-packages/gunicorn/arbiter.py", line 232, in run
    self.halt(reason=inst.reason, exit_status=inst.exit_status)
  File "/home/devanks/pythonMainProject/lib/python3.6/site-packages/gunicorn/arbiter.py", line 345, in halt
    self.stop()
  File "/home/devanks/pythonMainProject/lib/python3.6/site-packages/gunicorn/arbiter.py", line 393, in stop
    time.sleep(0.1)
  File "/home/devanks/pythonMainProject/lib/python3.6/site-packages/gunicorn/arbiter.py", line 245, in handle_chld
    self.reap_workers()
  File "/home/devanks/pythonMainProject/lib/python3.6/site-packages/gunicorn/arbiter.py", line 525, in reap_workers
    raise HaltServer(reason, self.WORKER_BOOT_ERROR)
gunicorn.errors.HaltServer: <HaltServer 'Worker failed to boot.' 3>
[2019-04-29 06:06:11 +0530] [10769] [INFO] Starting gunicorn 19.9.0
[2019-04-29 06:06:11 +0530] [10769] [INFO] Listening at: http://0.0.0.0:8001 (10769)
[2019-04-29 06:06:11 +0530] [10769] [INFO] Using worker: sync
[2019-04-29 06:06:11 +0530] [10772] [INFO] Booting worker with pid: 10772
[2019-04-29 06:06:11 +0530] [10774] [INFO] Booting worker with pid: 10774
[2019-04-29 00:36:11 +0000] [10772] [ERROR] Exception in worker process
Traceback (most recent call last):
  File "/home/devanks/pythonMainProject/lib/python3.6/site-packages/gunicorn/arbiter.py", line 583, in spawn_worker
    worker.init_process()
  File "/home/devanks/pythonMainProject/lib/python3.6/site-packages/gunicorn/workers/base.py", line 129, in init_process
    self.load_wsgi()
  File "/home/devanks/pythonMainProject/lib/python3.6/site-packages/gunicorn/workers/base.py", line 138, in load_wsgi
    self.wsgi = self.app.wsgi()
  File "/home/devanks/pythonMainProject/lib/python3.6/site-packages/gunicorn/app/base.py", line 67, in wsgi
    self.callable = self.load()
  File "/home/devanks/pythonMainProject/lib/python3.6/site-packages/gunicorn/app/wsgiapp.py", line 52, in load
    return self.load_wsgiapp()
  File "/home/devanks/pythonMainProject/lib/python3.6/site-packages/gunicorn/app/wsgiapp.py", line 41, in load_wsgiapp
    return util.import_app(self.app_uri)
  File "/home/devanks/pythonMainProject/lib/python3.6/site-packages/gunicorn/util.py", line 350, in import_app
    __import__(module)
  File "/home/devanks/AttendanceMgmtAI/Backend/AttendanceMgmtAI/wsgi.py", line 16, in <module>
    application = get_wsgi_application()
  File "/home/devanks/pythonMainProject/lib/python3.6/site-packages/django/core/wsgi.py", line 12, in get_wsgi_application
    django.setup(set_prefix=False)
  File "/home/devanks/pythonMainProject/lib/python3.6/site-packages/django/__init__.py", line 24, in setup
    apps.populate(settings.INSTALLED_APPS)
  File "/home/devanks/pythonMainProject/lib/python3.6/site-packages/django/apps/registry.py", line 91, in populate
    app_config = AppConfig.create(entry)
  File "/home/devanks/pythonMainProject/lib/python3.6/site-packages/django/apps/config.py", line 90, in create
    module = import_module(entry)
  File "/home/devanks/pythonMainProject/lib/python3.6/importlib/__init__.py", line 126, in import_module
    return _bootstrap._gcd_import(name[level:], package, level)
ModuleNotFoundError: No module named 'pwa'
[2019-04-29 00:36:11 +0000] [10772] [INFO] Worker exiting (pid: 10772)
[2019-04-29 00:36:11 +0000] [10774] [ERROR] Exception in worker process
Traceback (most recent call last):
  File "/home/devanks/pythonMainProject/lib/python3.6/site-packages/gunicorn/arbiter.py", line 583, in spawn_worker
    worker.init_process()
  File "/home/devanks/pythonMainProject/lib/python3.6/site-packages/gunicorn/workers/base.py", line 129, in init_process
    self.load_wsgi()
  File "/home/devanks/pythonMainProject/lib/python3.6/site-packages/gunicorn/workers/base.py", line 138, in load_wsgi
    self.wsgi = self.app.wsgi()
  File "/home/devanks/pythonMainProject/lib/python3.6/site-packages/gunicorn/app/base.py", line 67, in wsgi
    self.callable = self.load()
  File "/home/devanks/pythonMainProject/lib/python3.6/site-packages/gunicorn/app/wsgiapp.py", line 52, in load
    return self.load_wsgiapp()
  File "/home/devanks/pythonMainProject/lib/python3.6/site-packages/gunicorn/app/wsgiapp.py", line 41, in load_wsgiapp
    return util.import_app(self.app_uri)
  File "/home/devanks/pythonMainProject/lib/python3.6/site-packages/gunicorn/util.py", line 350, in import_app
    __import__(module)
  File "/home/devanks/AttendanceMgmtAI/Backend/AttendanceMgmtAI/wsgi.py", line 16, in <module>
    application = get_wsgi_application()
  File "/home/devanks/pythonMainProject/lib/python3.6/site-packages/django/core/wsgi.py", line 12, in get_wsgi_application
    django.setup(set_prefix=False)
  File "/home/devanks/pythonMainProject/lib/python3.6/site-packages/django/__init__.py", line 24, in setup
    apps.populate(settings.INSTALLED_APPS)
  File "/home/devanks/pythonMainProject/lib/python3.6/site-packages/django/apps/registry.py", line 91, in populate
    app_config = AppConfig.create(entry)
  File "/home/devanks/pythonMainProject/lib/python3.6/site-packages/django/apps/config.py", line 90, in create
    module = import_module(entry)
  File "/home/devanks/pythonMainProject/lib/python3.6/importlib/__init__.py", line 126, in import_module
    return _bootstrap._gcd_import(name[level:], package, level)
ModuleNotFoundError: No module named 'pwa'
[2019-04-29 00:36:11 +0000] [10774] [INFO] Worker exiting (pid: 10774)
Traceback (most recent call last):
  File "/home/devanks/pythonMainProject/lib/python3.6/site-packages/gunicorn/arbiter.py", line 203, in run
    self.manage_workers()
  File "/home/devanks/pythonMainProject/lib/python3.6/site-packages/gunicorn/arbiter.py", line 545, in manage_workers
    self.spawn_workers()
  File "/home/devanks/pythonMainProject/lib/python3.6/site-packages/gunicorn/arbiter.py", line 617, in spawn_workers
    time.sleep(0.1 * random.random())
  File "/home/devanks/pythonMainProject/lib/python3.6/site-packages/gunicorn/arbiter.py", line 245, in handle_chld
    self.reap_workers()
  File "/home/devanks/pythonMainProject/lib/python3.6/site-packages/gunicorn/arbiter.py", line 525, in reap_workers
    raise HaltServer(reason, self.WORKER_BOOT_ERROR)
gunicorn.errors.HaltServer: <HaltServer 'Worker failed to boot.' 3>

During handling of the above exception, another exception occurred:

Traceback (most recent call last):
  File "/home/devanks/pythonMainProject/bin/gunicorn", line 10, in <module>
    sys.exit(run())
  File "/home/devanks/pythonMainProject/lib/python3.6/site-packages/gunicorn/app/wsgiapp.py", line 61, in run
    WSGIApplication("%(prog)s [OPTIONS] [APP_MODULE]").run()
  File "/home/devanks/pythonMainProject/lib/python3.6/site-packages/gunicorn/app/base.py", line 223, in run
    super(Application, self).run()
  File "/home/devanks/pythonMainProject/lib/python3.6/site-packages/gunicorn/app/base.py", line 72, in run
    Arbiter(self).run()
  File "/home/devanks/pythonMainProject/lib/python3.6/site-packages/gunicorn/arbiter.py", line 232, in run
    self.halt(reason=inst.reason, exit_status=inst.exit_status)
  File "/home/devanks/pythonMainProject/lib/python3.6/site-packages/gunicorn/arbiter.py", line 345, in halt
    self.stop()
  File "/home/devanks/pythonMainProject/lib/python3.6/site-packages/gunicorn/arbiter.py", line 393, in stop
    time.sleep(0.1)
  File "/home/devanks/pythonMainProject/lib/python3.6/site-packages/gunicorn/arbiter.py", line 245, in handle_chld
    self.reap_workers()
  File "/home/devanks/pythonMainProject/lib/python3.6/site-packages/gunicorn/arbiter.py", line 525, in reap_workers
    raise HaltServer(reason, self.WORKER_BOOT_ERROR)
gunicorn.errors.HaltServer: <HaltServer 'Worker failed to boot.' 3>
